test OK
# bot BOTRIX_ETH_HEL executed
# bot BOTRIX_ETH_ANI executed
# bot BOTRIX_MATIC_ANI executed
# bot BOTRIX executed
We're done
#  29/09/2022 17:00:02
# bot BOTRIX_ETH_HEL executed
# bot BOTRIX_ETH_ANI executed
# bot BOTRIX_MATIC_ANI executed
# bot BOTRIX executed
We're done


#  29/09/2022 18:00:02
# bot BOTRIX_ETH_HEL executed
# bot BOTRIX_ETH_ANI executed
Traceback (most recent call last):
  File "./templates/trix_template/TrixFtxlive.py", line 70, in <module>
    data = client.get_historical_data(
  File "/home/anisse9/bot_app/.env/lib/python3.8/site-packages/ftx/api.py", line 415, in get_historical_data
    return self._get(
  File "/home/anisse9/bot_app/.env/lib/python3.8/site-packages/ftx/api.py", line 25, in _get
    return self._request('GET', path, params=params)
  File "/home/anisse9/bot_app/.env/lib/python3.8/site-packages/ftx/api.py", line 41, in _request
    return self._process_response(response)
  File "/home/anisse9/bot_app/.env/lib/python3.8/site-packages/ftx/api.py", line 68, in _process_response
    raise Exception(data['error'])
Exception: Please retry request
#  29/09/2022 19:00:02
# bot BOTRIX_ETH_HEL executed
# bot BOTRIX_ETH_ANI executed
# bot BOTRIX_MATIC_ANI executed
# bot BOTRIX executed
We're done


#  29/09/2022 20:00:02
# bot BOTRIX_ETH_HEL executed
# bot BOTRIX_ETH_ANI executed
# bot BOTRIX_MATIC_ANI executed
# bot BOTRIX executed
We're done


#  29/09/2022 21:00:02
# bot BOTRIX_ETH_HEL executed
# bot BOTRIX_ETH_ANI executed
# bot BOTRIX_MATIC_ANI executed
# bot BOTRIX executed
We're done


#  29/09/2022 22:00:01
# bot BOTRIX_ETH_HEL executed
# bot BOTRIX_ETH_ANI executed
# bot BOTRIX_MATIC_ANI executed
# bot BOTRIX executed
We're done


#  29/09/2022 23:00:02
# bot BOTRIX_ETH_HEL executed
# bot BOTRIX_ETH_ANI executed
# bot BOTRIX_MATIC_ANI executed
# bot BOTRIX executed
We're done


#  30/09/2022 00:00:03
# bot BOTRIX_ETH_HEL executed
# bot BOTRIX_ETH_ANI executed
# bot BOTRIX_MATIC_ANI executed
# bot BOTRIX executed
We're done


#  30/09/2022 01:00:02
# bot BOTRIX_ETH_HEL executed
# bot BOTRIX_ETH_ANI executed
# bot BOTRIX_MATIC_ANI executed
# bot BOTRIX executed
We're done


#  30/09/2022 02:00:02
# bot BOTRIX_ETH_HEL executed
# bot BOTRIX_ETH_ANI executed
# bot BOTRIX_MATIC_ANI executed
# bot BOTRIX executed
We're done


#  30/09/2022 03:00:02
# bot BOTRIX_ETH_HEL executed
# bot BOTRIX_ETH_ANI executed
# bot BOTRIX_MATIC_ANI executed
# bot BOTRIX executed
We're done


#  30/09/2022 04:00:02
# bot BOTRIX_ETH_HEL executed
# bot BOTRIX_ETH_ANI executed
# bot BOTRIX_MATIC_ANI executed
# bot BOTRIX executed
We're done


#  30/09/2022 05:00:02
# bot BOTRIX_ETH_HEL executed
# bot BOTRIX_ETH_ANI executed
# bot BOTRIX_MATIC_ANI executed
# bot BOTRIX executed
We're done


#  30/09/2022 06:00:02
# bot BOTRIX_ETH_HEL executed
# bot BOTRIX_ETH_ANI executed
# bot BOTRIX_MATIC_ANI executed
# bot BOTRIX executed
We're done


#  30/09/2022 07:00:02
# bot BOTRIX_ETH_HEL executed
# bot BOTRIX_ETH_ANI executed
# bot BOTRIX_MATIC_ANI executed
# bot BOTRIX executed
We're done


#  30/09/2022 08:00:02
# bot BOTRIX_ETH_HEL executed
# bot BOTRIX_ETH_ANI executed
# bot BOTRIX_MATIC_ANI executed
# bot BOTRIX executed
We're done


#  30/09/2022 09:00:02
# bot BOTRIX_ETH_HEL executed
# bot BOTRIX_ETH_ANI executed
# bot BOTRIX_MATIC_ANI executed
# bot BOTRIX executed
We're done


#  30/09/2022 10:00:01
# bot BOTRIX_ETH_HEL executed
# bot BOTRIX_ETH_ANI executed
# bot BOTRIX_MATIC_ANI executed
# bot BOTRIX executed
We're done


#  30/09/2022 11:00:02
# bot BOTRIX_ETH_HEL executed
# bot BOTRIX_ETH_ANI executed
# bot BOTRIX_MATIC_ANI executed
# bot BOTRIX executed
We're done


#  30/09/2022 12:00:02
# bot BOTRIX_ETH_HEL executed
# bot BOTRIX_ETH_ANI executed
# bot BOTRIX_MATIC_ANI executed
# bot BOTRIX executed
We're done


#  30/09/2022 13:00:02
# bot BOTRIX_ETH_HEL executed
# bot BOTRIX_ETH_ANI executed
# bot BOTRIX_MATIC_ANI executed
# bot BOTRIX executed
We're done


#  30/09/2022 14:00:02
# bot BOTRIX_ETH_HEL executed
# bot BOTRIX_ETH_ANI executed
# bot BOTRIX_MATIC_ANI executed
# bot BOTRIX executed
We're done


#  30/09/2022 15:00:02
# bot BOTRIX_ETH_HEL executed
# bot BOTRIX_ETH_ANI executed
# bot BOTRIX_MATIC_ANI executed
# bot BOTRIX executed
We're done


#  30/09/2022 16:00:02
# bot BOTRIX_ETH_HEL executed
# bot BOTRIX_ETH_ANI executed
# bot BOTRIX_MATIC_ANI executed
# bot BOTRIX executed
We're done


#  30/09/2022 17:00:02
# bot BOTRIX_ETH_HEL executed
# bot BOTRIX_ETH_ANI executed
# bot BOTRIX_MATIC_ANI executed
# bot BOTRIX executed
We're done


#  30/09/2022 18:00:02
# bot BOTRIX_ETH_HEL executed
# bot BOTRIX_ETH_ANI executed
# bot BOTRIX_MATIC_ANI executed
# bot BOTRIX executed
We're done


#  30/09/2022 19:00:02
# bot BOTRIX_ETH_HEL executed
# bot BOTRIX_ETH_ANI executed
# bot BOTRIX_MATIC_ANI executed
# bot BOTRIX executed
We're done


#  30/09/2022 20:00:01
# bot BOTRIX_ETH_HEL executed
# bot BOTRIX_ETH_ANI executed
# bot BOTRIX_MATIC_ANI executed
Traceback (most recent call last):
  File "./templates/trix_template/TrixFtxlive.py", line 70, in <module>
    data = client.get_historical_data(
  File "/home/anisse9/bot_app/.env/lib/python3.8/site-packages/ftx/api.py", line 415, in get_historical_data
    return self._get(
  File "/home/anisse9/bot_app/.env/lib/python3.8/site-packages/ftx/api.py", line 25, in _get
    return self._request('GET', path, params=params)
  File "/home/anisse9/bot_app/.env/lib/python3.8/site-packages/ftx/api.py", line 41, in _request
    return self._process_response(response)
  File "/home/anisse9/bot_app/.env/lib/python3.8/site-packages/ftx/api.py", line 68, in _process_response
    raise Exception(data['error'])
Exception: Please retry request
#  30/09/2022 21:00:02
# bot BOTRIX_ETH_HEL executed
# bot BOTRIX_ETH_ANI executed
# bot BOTRIX_MATIC_ANI executed
# bot BOTRIX executed
We're done


#  30/09/2022 22:00:02
# bot BOTRIX_ETH_HEL executed
# bot BOTRIX_ETH_ANI executed
# bot BOTRIX_MATIC_ANI executed
# bot BOTRIX executed
We're done


#  30/09/2022 23:00:02
# bot BOTRIX_ETH_HEL executed
# bot BOTRIX_ETH_ANI executed
# bot BOTRIX_MATIC_ANI executed
# bot BOTRIX executed
We're done


#  01/10/2022 00:00:02
# bot BOTRIX_ETH_HEL executed
# bot BOTRIX_ETH_ANI executed
# bot BOTRIX_MATIC_ANI executed
on vent :subaccount_name BOTRIX
# bot BOTRIX executed
We're done


#  01/10/2022 01:00:02
# bot BOTRIX_ETH_HEL executed
# bot BOTRIX_ETH_ANI executed
# bot BOTRIX_MATIC_ANI executed
# bot BOTRIX executed
We're done


#  01/10/2022 02:00:02
# bot BOTRIX_ETH_HEL executed
on vent :subaccount_name BOTRIX_ETH_ANI
# bot BOTRIX_ETH_ANI executed
# bot BOTRIX_MATIC_ANI executed
# bot BOTRIX executed
We're done


#  01/10/2022 03:00:02
# bot BOTRIX_ETH_HEL executed
# bot BOTRIX_ETH_ANI executed
# bot BOTRIX_MATIC_ANI executed
# bot BOTRIX executed
We're done


#  01/10/2022 04:00:02
# bot BOTRIX_ETH_HEL executed
# bot BOTRIX_ETH_ANI executed
# bot BOTRIX_MATIC_ANI executed
# bot BOTRIX executed
We're done


#  01/10/2022 05:00:02
# bot BOTRIX_ETH_HEL executed
# bot BOTRIX_ETH_ANI executed
# bot BOTRIX_MATIC_ANI executed
# bot BOTRIX executed
We're done


#  01/10/2022 06:00:02
# bot BOTRIX_ETH_HEL executed
# bot BOTRIX_ETH_ANI executed
# bot BOTRIX_MATIC_ANI executed
# bot BOTRIX executed
We're done


#  01/10/2022 07:00:02
# bot BOTRIX_ETH_HEL executed
# bot BOTRIX_ETH_ANI executed
# bot BOTRIX_MATIC_ANI executed
# bot BOTRIX executed
We're done


#  01/10/2022 08:00:02
on vent :subaccount_name BOTRIX_ETH_HEL
# bot BOTRIX_ETH_HEL executed
# bot BOTRIX_ETH_ANI executed
# bot BOTRIX_MATIC_ANI executed
# bot BOTRIX executed
We're done


#  01/10/2022 09:00:02
# bot BOTRIX_ETH_HEL executed
# bot BOTRIX_ETH_ANI executed
# bot BOTRIX_MATIC_ANI executed
# bot BOTRIX executed
We're done


#  01/10/2022 10:00:02
# bot BOTRIX_ETH_HEL executed
# bot BOTRIX_ETH_ANI executed
# bot BOTRIX_MATIC_ANI executed
# bot BOTRIX executed
We're done


#  01/10/2022 11:00:02
# bot BOTRIX_ETH_HEL executed
# bot BOTRIX_ETH_ANI executed
# bot BOTRIX_MATIC_ANI executed
# bot BOTRIX executed
We're done


#  01/10/2022 12:00:02
# bot BOTRIX_ETH_HEL executed
# bot BOTRIX_ETH_ANI executed
# bot BOTRIX_MATIC_ANI executed
# bot BOTRIX executed
We're done


#  01/10/2022 13:00:02
# bot BOTRIX_ETH_HEL executed
# bot BOTRIX_ETH_ANI executed
# bot BOTRIX_MATIC_ANI executed
# bot BOTRIX executed
We're done


#  01/10/2022 14:00:02
# bot BOTRIX_ETH_HEL executed
# bot BOTRIX_ETH_ANI executed
# bot BOTRIX_MATIC_ANI executed
# bot BOTRIX executed
We're done


#  01/10/2022 15:00:02
# bot BOTRIX_ETH_HEL executed
# bot BOTRIX_ETH_ANI executed
# bot BOTRIX_MATIC_ANI executed
# bot BOTRIX executed
We're done


#  01/10/2022 16:00:02
# bot BOTRIX_ETH_HEL executed
# bot BOTRIX_ETH_ANI executed
# bot BOTRIX_MATIC_ANI executed
# bot BOTRIX executed
We're done


#  01/10/2022 17:00:02
Traceback (most recent call last):
  File "/home/anisse9/bot_app/.env/lib/python3.8/site-packages/mysql/connector/connection_cext.py", line 555, in cmd_query
    self._cmysql.query(
_mysql_connector.MySQLInterfaceError: You have an error in your SQL syntax; check the manual that corresponds to your MySQL server version for the right syntax to use near '' at line 2

The above exception was the direct cause of the following exception:

Traceback (most recent call last):
  File "./templates/trix_template/TrixFtxlive.py", line 123, in <module>
    con.insert_trix_balence(datetime.now(), f"Trix : {i[4]}_len{i[5]}_sign{i[6]}_top{i[7]}_bottom{i[8]}_RSI{i[9]}", listBalances[0]['total'], i[10])
  File "/home/anisse9/bot_app/bdd_communication.py", line 76, in insert_trix_balence
    cursor.execute(query)
  File "/home/anisse9/bot_app/.env/lib/python3.8/site-packages/mysql/connector/cursor_cext.py", line 276, in execute
    result = self._cnx.cmd_query(
  File "/home/anisse9/bot_app/.env/lib/python3.8/site-packages/mysql/connector/connection_cext.py", line 563, in cmd_query
    raise get_mysql_exception(
mysql.connector.errors.ProgrammingError: 1064 (42000): You have an error in your SQL syntax; check the manual that corresponds to your MySQL server version for the right syntax to use near '' at line 2
#  01/10/2022 18:00:02
Traceback (most recent call last):
  File "/home/anisse9/bot_app/.env/lib/python3.8/site-packages/mysql/connector/connection_cext.py", line 555, in cmd_query
    self._cmysql.query(
_mysql_connector.MySQLInterfaceError: You have an error in your SQL syntax; check the manual that corresponds to your MySQL server version for the right syntax to use near '' at line 2

The above exception was the direct cause of the following exception:

Traceback (most recent call last):
  File "./templates/trix_template/TrixFtxlive.py", line 123, in <module>
    con.insert_trix_balence(datetime.now(), f"Trix : {i[4]}_len{i[5]}_sign{i[6]}_top{i[7]}_bottom{i[8]}_RSI{i[9]}", listBalances[0]['total'], i[10])
  File "/home/anisse9/bot_app/bdd_communication.py", line 76, in insert_trix_balence
    cursor.execute(query)
  File "/home/anisse9/bot_app/.env/lib/python3.8/site-packages/mysql/connector/cursor_cext.py", line 276, in execute
    result = self._cnx.cmd_query(
  File "/home/anisse9/bot_app/.env/lib/python3.8/site-packages/mysql/connector/connection_cext.py", line 563, in cmd_query
    raise get_mysql_exception(
mysql.connector.errors.ProgrammingError: 1064 (42000): You have an error in your SQL syntax; check the manual that corresponds to your MySQL server version for the right syntax to use near '' at line 2
#  01/10/2022 19:00:02
Traceback (most recent call last):
  File "/home/anisse9/bot_app/.env/lib/python3.8/site-packages/mysql/connector/connection_cext.py", line 555, in cmd_query
    self._cmysql.query(
_mysql_connector.MySQLInterfaceError: You have an error in your SQL syntax; check the manual that corresponds to your MySQL server version for the right syntax to use near '' at line 2

The above exception was the direct cause of the following exception:

Traceback (most recent call last):
  File "./templates/trix_template/TrixFtxlive.py", line 123, in <module>
    con.insert_trix_balence(datetime.now(), f"Trix : {i[4]}_len{i[5]}_sign{i[6]}_top{i[7]}_bottom{i[8]}_RSI{i[9]}", listBalances[0]['total'], i[10])
  File "/home/anisse9/bot_app/bdd_communication.py", line 76, in insert_trix_balence
    cursor.execute(query)
  File "/home/anisse9/bot_app/.env/lib/python3.8/site-packages/mysql/connector/cursor_cext.py", line 276, in execute
    result = self._cnx.cmd_query(
  File "/home/anisse9/bot_app/.env/lib/python3.8/site-packages/mysql/connector/connection_cext.py", line 563, in cmd_query
    raise get_mysql_exception(
mysql.connector.errors.ProgrammingError: 1064 (42000): You have an error in your SQL syntax; check the manual that corresponds to your MySQL server version for the right syntax to use near '' at line 2
#  01/10/2022 20:00:01
Traceback (most recent call last):
  File "/home/anisse9/bot_app/.env/lib/python3.8/site-packages/mysql/connector/connection_cext.py", line 555, in cmd_query
    self._cmysql.query(
_mysql_connector.MySQLInterfaceError: You have an error in your SQL syntax; check the manual that corresponds to your MySQL server version for the right syntax to use near '' at line 2

The above exception was the direct cause of the following exception:

Traceback (most recent call last):
  File "./templates/trix_template/TrixFtxlive.py", line 123, in <module>
    con.insert_trix_balence(datetime.now(), f"Trix : {i[4]}_len{i[5]}_sign{i[6]}_top{i[7]}_bottom{i[8]}_RSI{i[9]}", listBalances[0]['total'], i[10])
  File "/home/anisse9/bot_app/bdd_communication.py", line 76, in insert_trix_balence
    cursor.execute(query)
  File "/home/anisse9/bot_app/.env/lib/python3.8/site-packages/mysql/connector/cursor_cext.py", line 276, in execute
    result = self._cnx.cmd_query(
  File "/home/anisse9/bot_app/.env/lib/python3.8/site-packages/mysql/connector/connection_cext.py", line 563, in cmd_query
    raise get_mysql_exception(
mysql.connector.errors.ProgrammingError: 1064 (42000): You have an error in your SQL syntax; check the manual that corresponds to your MySQL server version for the right syntax to use near '' at line 2
#  01/10/2022 21:00:02
Traceback (most recent call last):
  File "/home/anisse9/bot_app/.env/lib/python3.8/site-packages/mysql/connector/connection_cext.py", line 555, in cmd_query
    self._cmysql.query(
_mysql_connector.MySQLInterfaceError: You have an error in your SQL syntax; check the manual that corresponds to your MySQL server version for the right syntax to use near '' at line 2

The above exception was the direct cause of the following exception:

Traceback (most recent call last):
  File "./templates/trix_template/TrixFtxlive.py", line 123, in <module>
    con.insert_trix_balence(datetime.now(), f"Trix : {i[4]}_len{i[5]}_sign{i[6]}_top{i[7]}_bottom{i[8]}_RSI{i[9]}", listBalances[0]['total'], i[10])
  File "/home/anisse9/bot_app/bdd_communication.py", line 76, in insert_trix_balence
    cursor.execute(query)
  File "/home/anisse9/bot_app/.env/lib/python3.8/site-packages/mysql/connector/cursor_cext.py", line 276, in execute
    result = self._cnx.cmd_query(
  File "/home/anisse9/bot_app/.env/lib/python3.8/site-packages/mysql/connector/connection_cext.py", line 563, in cmd_query
    raise get_mysql_exception(
mysql.connector.errors.ProgrammingError: 1064 (42000): You have an error in your SQL syntax; check the manual that corresponds to your MySQL server version for the right syntax to use near '' at line 2
#  01/10/2022 22:00:02
Traceback (most recent call last):
  File "/home/anisse9/bot_app/.env/lib/python3.8/site-packages/mysql/connector/connection_cext.py", line 555, in cmd_query
    self._cmysql.query(
_mysql_connector.MySQLInterfaceError: You have an error in your SQL syntax; check the manual that corresponds to your MySQL server version for the right syntax to use near '' at line 2

The above exception was the direct cause of the following exception:

Traceback (most recent call last):
  File "./templates/trix_template/TrixFtxlive.py", line 123, in <module>
    con.insert_trix_balence(datetime.now(), f"Trix : {i[4]}_len{i[5]}_sign{i[6]}_top{i[7]}_bottom{i[8]}_RSI{i[9]}", listBalances[0]['total'], i[10])
  File "/home/anisse9/bot_app/bdd_communication.py", line 76, in insert_trix_balence
    cursor.execute(query)
  File "/home/anisse9/bot_app/.env/lib/python3.8/site-packages/mysql/connector/cursor_cext.py", line 276, in execute
    result = self._cnx.cmd_query(
  File "/home/anisse9/bot_app/.env/lib/python3.8/site-packages/mysql/connector/connection_cext.py", line 563, in cmd_query
    raise get_mysql_exception(
mysql.connector.errors.ProgrammingError: 1064 (42000): You have an error in your SQL syntax; check the manual that corresponds to your MySQL server version for the right syntax to use near '' at line 2
#  01/10/2022 23:00:02
Traceback (most recent call last):
  File "/home/anisse9/bot_app/.env/lib/python3.8/site-packages/mysql/connector/connection_cext.py", line 555, in cmd_query
    self._cmysql.query(
_mysql_connector.MySQLInterfaceError: You have an error in your SQL syntax; check the manual that corresponds to your MySQL server version for the right syntax to use near '' at line 2

The above exception was the direct cause of the following exception:

Traceback (most recent call last):
  File "./templates/trix_template/TrixFtxlive.py", line 123, in <module>
    con.insert_trix_balence(datetime.now(), f"Trix : {i[4]}_len{i[5]}_sign{i[6]}_top{i[7]}_bottom{i[8]}_RSI{i[9]}", listBalances[0]['total'], i[10])
  File "/home/anisse9/bot_app/bdd_communication.py", line 76, in insert_trix_balence
    cursor.execute(query)
  File "/home/anisse9/bot_app/.env/lib/python3.8/site-packages/mysql/connector/cursor_cext.py", line 276, in execute
    result = self._cnx.cmd_query(
  File "/home/anisse9/bot_app/.env/lib/python3.8/site-packages/mysql/connector/connection_cext.py", line 563, in cmd_query
    raise get_mysql_exception(
mysql.connector.errors.ProgrammingError: 1064 (42000): You have an error in your SQL syntax; check the manual that corresponds to your MySQL server version for the right syntax to use near '' at line 2
#  02/10/2022 00:00:02
Traceback (most recent call last):
  File "/home/anisse9/bot_app/.env/lib/python3.8/site-packages/mysql/connector/connection_cext.py", line 555, in cmd_query
    self._cmysql.query(
_mysql_connector.MySQLInterfaceError: You have an error in your SQL syntax; check the manual that corresponds to your MySQL server version for the right syntax to use near '' at line 2

The above exception was the direct cause of the following exception:

Traceback (most recent call last):
  File "./templates/trix_template/TrixFtxlive.py", line 123, in <module>
    con.insert_trix_balence(datetime.now(), f"Trix : {i[4]}_len{i[5]}_sign{i[6]}_top{i[7]}_bottom{i[8]}_RSI{i[9]}", listBalances[0]['total'], i[10])
  File "/home/anisse9/bot_app/bdd_communication.py", line 76, in insert_trix_balence
    cursor.execute(query)
  File "/home/anisse9/bot_app/.env/lib/python3.8/site-packages/mysql/connector/cursor_cext.py", line 276, in execute
    result = self._cnx.cmd_query(
  File "/home/anisse9/bot_app/.env/lib/python3.8/site-packages/mysql/connector/connection_cext.py", line 563, in cmd_query
    raise get_mysql_exception(
mysql.connector.errors.ProgrammingError: 1064 (42000): You have an error in your SQL syntax; check the manual that corresponds to your MySQL server version for the right syntax to use near '' at line 2
#  02/10/2022 01:00:02
Traceback (most recent call last):
  File "/home/anisse9/bot_app/.env/lib/python3.8/site-packages/mysql/connector/connection_cext.py", line 555, in cmd_query
    self._cmysql.query(
_mysql_connector.MySQLInterfaceError: You have an error in your SQL syntax; check the manual that corresponds to your MySQL server version for the right syntax to use near '' at line 2

The above exception was the direct cause of the following exception:

Traceback (most recent call last):
  File "./templates/trix_template/TrixFtxlive.py", line 123, in <module>
    con.insert_trix_balence(datetime.now(), f"Trix : {i[4]}_len{i[5]}_sign{i[6]}_top{i[7]}_bottom{i[8]}_RSI{i[9]}", listBalances[0]['total'], i[10])
  File "/home/anisse9/bot_app/bdd_communication.py", line 76, in insert_trix_balence
    cursor.execute(query)
  File "/home/anisse9/bot_app/.env/lib/python3.8/site-packages/mysql/connector/cursor_cext.py", line 276, in execute
    result = self._cnx.cmd_query(
  File "/home/anisse9/bot_app/.env/lib/python3.8/site-packages/mysql/connector/connection_cext.py", line 563, in cmd_query
    raise get_mysql_exception(
mysql.connector.errors.ProgrammingError: 1064 (42000): You have an error in your SQL syntax; check the manual that corresponds to your MySQL server version for the right syntax to use near '' at line 2
#  02/10/2022 02:00:02
Traceback (most recent call last):
  File "/home/anisse9/bot_app/.env/lib/python3.8/site-packages/mysql/connector/connection_cext.py", line 555, in cmd_query
    self._cmysql.query(
_mysql_connector.MySQLInterfaceError: You have an error in your SQL syntax; check the manual that corresponds to your MySQL server version for the right syntax to use near '' at line 2

The above exception was the direct cause of the following exception:

Traceback (most recent call last):
  File "./templates/trix_template/TrixFtxlive.py", line 123, in <module>
    con.insert_trix_balence(datetime.now(), f"Trix : {i[4]}_len{i[5]}_sign{i[6]}_top{i[7]}_bottom{i[8]}_RSI{i[9]}", listBalances[0]['total'], i[10])
  File "/home/anisse9/bot_app/bdd_communication.py", line 76, in insert_trix_balence
    cursor.execute(query)
  File "/home/anisse9/bot_app/.env/lib/python3.8/site-packages/mysql/connector/cursor_cext.py", line 276, in execute
    result = self._cnx.cmd_query(
  File "/home/anisse9/bot_app/.env/lib/python3.8/site-packages/mysql/connector/connection_cext.py", line 563, in cmd_query
    raise get_mysql_exception(
mysql.connector.errors.ProgrammingError: 1064 (42000): You have an error in your SQL syntax; check the manual that corresponds to your MySQL server version for the right syntax to use near '' at line 2
#  02/10/2022 03:00:02
Traceback (most recent call last):
  File "/home/anisse9/bot_app/.env/lib/python3.8/site-packages/mysql/connector/connection_cext.py", line 555, in cmd_query
    self._cmysql.query(
_mysql_connector.MySQLInterfaceError: You have an error in your SQL syntax; check the manual that corresponds to your MySQL server version for the right syntax to use near '' at line 2

The above exception was the direct cause of the following exception:

Traceback (most recent call last):
  File "./templates/trix_template/TrixFtxlive.py", line 123, in <module>
    con.insert_trix_balence(datetime.now(), f"Trix : {i[4]}_len{i[5]}_sign{i[6]}_top{i[7]}_bottom{i[8]}_RSI{i[9]}", listBalances[0]['total'], i[10])
  File "/home/anisse9/bot_app/bdd_communication.py", line 76, in insert_trix_balence
    cursor.execute(query)
  File "/home/anisse9/bot_app/.env/lib/python3.8/site-packages/mysql/connector/cursor_cext.py", line 276, in execute
    result = self._cnx.cmd_query(
  File "/home/anisse9/bot_app/.env/lib/python3.8/site-packages/mysql/connector/connection_cext.py", line 563, in cmd_query
    raise get_mysql_exception(
mysql.connector.errors.ProgrammingError: 1064 (42000): You have an error in your SQL syntax; check the manual that corresponds to your MySQL server version for the right syntax to use near '' at line 2
#  02/10/2022 04:00:02
Traceback (most recent call last):
  File "/home/anisse9/bot_app/.env/lib/python3.8/site-packages/mysql/connector/connection_cext.py", line 555, in cmd_query
    self._cmysql.query(
_mysql_connector.MySQLInterfaceError: You have an error in your SQL syntax; check the manual that corresponds to your MySQL server version for the right syntax to use near '' at line 2

The above exception was the direct cause of the following exception:

Traceback (most recent call last):
  File "./templates/trix_template/TrixFtxlive.py", line 123, in <module>
    con.insert_trix_balence(datetime.now(), f"Trix : {i[4]}_len{i[5]}_sign{i[6]}_top{i[7]}_bottom{i[8]}_RSI{i[9]}", listBalances[0]['total'], i[10])
  File "/home/anisse9/bot_app/bdd_communication.py", line 76, in insert_trix_balence
    cursor.execute(query)
  File "/home/anisse9/bot_app/.env/lib/python3.8/site-packages/mysql/connector/cursor_cext.py", line 276, in execute
    result = self._cnx.cmd_query(
  File "/home/anisse9/bot_app/.env/lib/python3.8/site-packages/mysql/connector/connection_cext.py", line 563, in cmd_query
    raise get_mysql_exception(
mysql.connector.errors.ProgrammingError: 1064 (42000): You have an error in your SQL syntax; check the manual that corresponds to your MySQL server version for the right syntax to use near '' at line 2
#  02/10/2022 05:00:02
Traceback (most recent call last):
  File "/home/anisse9/bot_app/.env/lib/python3.8/site-packages/mysql/connector/connection_cext.py", line 555, in cmd_query
    self._cmysql.query(
_mysql_connector.MySQLInterfaceError: You have an error in your SQL syntax; check the manual that corresponds to your MySQL server version for the right syntax to use near '' at line 2

The above exception was the direct cause of the following exception:

Traceback (most recent call last):
  File "./templates/trix_template/TrixFtxlive.py", line 123, in <module>
    con.insert_trix_balence(datetime.now(), f"Trix : {i[4]}_len{i[5]}_sign{i[6]}_top{i[7]}_bottom{i[8]}_RSI{i[9]}", listBalances[0]['total'], i[10])
  File "/home/anisse9/bot_app/bdd_communication.py", line 76, in insert_trix_balence
    cursor.execute(query)
  File "/home/anisse9/bot_app/.env/lib/python3.8/site-packages/mysql/connector/cursor_cext.py", line 276, in execute
    result = self._cnx.cmd_query(
  File "/home/anisse9/bot_app/.env/lib/python3.8/site-packages/mysql/connector/connection_cext.py", line 563, in cmd_query
    raise get_mysql_exception(
mysql.connector.errors.ProgrammingError: 1064 (42000): You have an error in your SQL syntax; check the manual that corresponds to your MySQL server version for the right syntax to use near '' at line 2
#  02/10/2022 06:00:02
Traceback (most recent call last):
  File "/home/anisse9/bot_app/.env/lib/python3.8/site-packages/mysql/connector/connection_cext.py", line 555, in cmd_query
    self._cmysql.query(
_mysql_connector.MySQLInterfaceError: You have an error in your SQL syntax; check the manual that corresponds to your MySQL server version for the right syntax to use near '' at line 2

The above exception was the direct cause of the following exception:

Traceback (most recent call last):
  File "./templates/trix_template/TrixFtxlive.py", line 123, in <module>
    con.insert_trix_balence(datetime.now(), f"Trix : {i[4]}_len{i[5]}_sign{i[6]}_top{i[7]}_bottom{i[8]}_RSI{i[9]}", listBalances[0]['total'], i[10])
  File "/home/anisse9/bot_app/bdd_communication.py", line 76, in insert_trix_balence
    cursor.execute(query)
  File "/home/anisse9/bot_app/.env/lib/python3.8/site-packages/mysql/connector/cursor_cext.py", line 276, in execute
    result = self._cnx.cmd_query(
  File "/home/anisse9/bot_app/.env/lib/python3.8/site-packages/mysql/connector/connection_cext.py", line 563, in cmd_query
    raise get_mysql_exception(
mysql.connector.errors.ProgrammingError: 1064 (42000): You have an error in your SQL syntax; check the manual that corresponds to your MySQL server version for the right syntax to use near '' at line 2
#  02/10/2022 07:00:02
Traceback (most recent call last):
  File "/home/anisse9/bot_app/.env/lib/python3.8/site-packages/mysql/connector/connection_cext.py", line 555, in cmd_query
    self._cmysql.query(
_mysql_connector.MySQLInterfaceError: You have an error in your SQL syntax; check the manual that corresponds to your MySQL server version for the right syntax to use near '' at line 2

The above exception was the direct cause of the following exception:

Traceback (most recent call last):
  File "./templates/trix_template/TrixFtxlive.py", line 123, in <module>
    con.insert_trix_balence(datetime.now(), f"Trix : {i[4]}_len{i[5]}_sign{i[6]}_top{i[7]}_bottom{i[8]}_RSI{i[9]}", listBalances[0]['total'], i[10])
  File "/home/anisse9/bot_app/bdd_communication.py", line 76, in insert_trix_balence
    cursor.execute(query)
  File "/home/anisse9/bot_app/.env/lib/python3.8/site-packages/mysql/connector/cursor_cext.py", line 276, in execute
    result = self._cnx.cmd_query(
  File "/home/anisse9/bot_app/.env/lib/python3.8/site-packages/mysql/connector/connection_cext.py", line 563, in cmd_query
    raise get_mysql_exception(
mysql.connector.errors.ProgrammingError: 1064 (42000): You have an error in your SQL syntax; check the manual that corresponds to your MySQL server version for the right syntax to use near '' at line 2
#  02/10/2022 08:00:02
# bot BOTRIX_ETH_HEL executed
# bot BOTRIX_ETH_ANI executed
# bot BOTRIX_MATIC_ANI executed
# bot BOTRIX executed
invalid api
invalid api
Traceback (most recent call last):
  File "./templates/trix_template/TrixFtxlive.py", line 126, in <module>
    listBalances = sorted(client.get_balances(),key= lambda d : d['total'], reverse= True)
  File "/home/anisse9/bot_app/.env/lib/python3.8/site-packages/ftx/api.py", line 81, in wrapped
    return fn(self, *args, **kwargs)
  File "/home/anisse9/bot_app/.env/lib/python3.8/site-packages/ftx/api.py", line 273, in get_balances
    return self._get('wallet/balances')
  File "/home/anisse9/bot_app/.env/lib/python3.8/site-packages/ftx/api.py", line 25, in _get
    return self._request('GET', path, params=params)
  File "/home/anisse9/bot_app/.env/lib/python3.8/site-packages/ftx/api.py", line 41, in _request
    return self._process_response(response)
  File "/home/anisse9/bot_app/.env/lib/python3.8/site-packages/ftx/api.py", line 68, in _process_response
    raise Exception(data['error'])
Exception: Invalid api key
#  02/10/2022 09:00:02
# bot BOTRIX_ETH_HEL executed
# bot BOTRIX_ETH_ANI executed
# bot BOTRIX_MATIC_ANI executed
# bot BOTRIX executed
Traceback (most recent call last):
  File "./templates/trix_template/TrixFtxlive.py", line 97, in <module>
    buyOrder = client.place_order(
  File "/home/anisse9/bot_app/.env/lib/python3.8/site-packages/ftx/api.py", line 81, in wrapped
    return fn(self, *args, **kwargs)
  File "/home/anisse9/bot_app/.env/lib/python3.8/site-packages/ftx/api.py", line 176, in place_order
    return self._post(
  File "/home/anisse9/bot_app/.env/lib/python3.8/site-packages/ftx/api.py", line 28, in _post
    return self._request('POST', path, json=params)
  File "/home/anisse9/bot_app/.env/lib/python3.8/site-packages/ftx/api.py", line 41, in _request
    return self._process_response(response)
  File "/home/anisse9/bot_app/.env/lib/python3.8/site-packages/ftx/api.py", line 68, in _process_response
    raise Exception(data['error'])
Exception: Must complete KYC level 2 to trade this product
#  02/10/2022 10:00:02
# bot BOTRIX_ETH_HEL executed
# bot BOTRIX_ETH_ANI executed
# bot BOTRIX_MATIC_ANI executed
# bot BOTRIX executed
We're done


#  02/10/2022 11:00:02
# bot BOTRIX_ETH_HEL executed
# bot BOTRIX_ETH_ANI executed
# bot BOTRIX_MATIC_ANI executed
# bot BOTRIX executed
We're done


#  02/10/2022 12:00:02
# bot BOTRIX_ETH_HEL executed
# bot BOTRIX_ETH_ANI executed
# bot BOTRIX_MATIC_ANI executed
# bot BOTRIX executed
We're done


#  02/10/2022 13:00:02
on vent :subaccount_name BOTRIX_ETH_HEL
# bot BOTRIX_ETH_HEL executed
on vent :subaccount_name BOTRIX_ETH_ANI
# bot BOTRIX_ETH_ANI executed
# bot BOTRIX_MATIC_ANI executed
on vent :subaccount_name BOTRIX
# bot BOTRIX executed
We're done


.env/bin/python: can't open file './templates/trix_template/TrixFtxlive.py': [Errno 2] No such file or directory
.env/bin/python: can't open file './templates/trix_template/TrixFtxlive.py': [Errno 2] No such file or directory
.env/bin/python: can't open file './templates/trix_template/TrixFtxlive.py': [Errno 2] No such file or directory
#  02/10/2022 17:00:02
# bot BOTRIX_ETH_HEL executed
# bot BOTRIX_ETH_ANI executed
# bot BOTRIX_MATIC_ANI executed
# bot BOTRIX executed
Traceback (most recent call last):
  File "./templates/trix_template/TrixFtxlive.py", line 70, in <module>
    data = client.get_historical_data(
  File "/home/anisse9/bot_app/.env/lib/python3.8/site-packages/ftx/api.py", line 415, in get_historical_data
    return self._get(
  File "/home/anisse9/bot_app/.env/lib/python3.8/site-packages/ftx/api.py", line 25, in _get
    return self._request('GET', path, params=params)
  File "/home/anisse9/bot_app/.env/lib/python3.8/site-packages/ftx/api.py", line 41, in _request
    return self._process_response(response)
  File "/home/anisse9/bot_app/.env/lib/python3.8/site-packages/ftx/api.py", line 68, in _process_response
    raise Exception(data['error'])
Exception: No such market: ATO/USD 
#  02/10/2022 18:00:02
# bot BOTRIX_ETH_HEL executed
# bot BOTRIX_ETH_ANI executed
# bot BOTRIX_MATIC_ANI executed
# bot BOTRIX executed
Traceback (most recent call last):
  File "./templates/trix_template/TrixFtxlive.py", line 70, in <module>
    data = client.get_historical_data(
  File "/home/anisse9/bot_app/.env/lib/python3.8/site-packages/ftx/api.py", line 415, in get_historical_data
    return self._get(
  File "/home/anisse9/bot_app/.env/lib/python3.8/site-packages/ftx/api.py", line 25, in _get
    return self._request('GET', path, params=params)
  File "/home/anisse9/bot_app/.env/lib/python3.8/site-packages/ftx/api.py", line 41, in _request
    return self._process_response(response)
  File "/home/anisse9/bot_app/.env/lib/python3.8/site-packages/ftx/api.py", line 68, in _process_response
    raise Exception(data['error'])
Exception: No such market: ATO/USD 
#  02/10/2022 19:00:02
# bot BOTRIX_ETH_HEL executed
# bot BOTRIX_ETH_ANI executed
# bot BOTRIX_MATIC_ANI executed
# bot BOTRIX executed
Traceback (most recent call last):
  File "./templates/trix_template/TrixFtxlive.py", line 70, in <module>
    data = client.get_historical_data(
  File "/home/anisse9/bot_app/.env/lib/python3.8/site-packages/ftx/api.py", line 415, in get_historical_data
    return self._get(
  File "/home/anisse9/bot_app/.env/lib/python3.8/site-packages/ftx/api.py", line 25, in _get
    return self._request('GET', path, params=params)
  File "/home/anisse9/bot_app/.env/lib/python3.8/site-packages/ftx/api.py", line 41, in _request
    return self._process_response(response)
  File "/home/anisse9/bot_app/.env/lib/python3.8/site-packages/ftx/api.py", line 68, in _process_response
    raise Exception(data['error'])
Exception: No such market: ATO/USD 
#  02/10/2022 20:00:02
# bot BOTRIX_ETH_HEL executed
# bot BOTRIX_ETH_ANI executed
# bot BOTRIX_MATIC_ANI executed
# bot BOTRIX executed
Traceback (most recent call last):
  File "./templates/trix_template/TrixFtxlive.py", line 70, in <module>
    data = client.get_historical_data(
  File "/home/anisse9/bot_app/.env/lib/python3.8/site-packages/ftx/api.py", line 415, in get_historical_data
    return self._get(
  File "/home/anisse9/bot_app/.env/lib/python3.8/site-packages/ftx/api.py", line 25, in _get
    return self._request('GET', path, params=params)
  File "/home/anisse9/bot_app/.env/lib/python3.8/site-packages/ftx/api.py", line 41, in _request
    return self._process_response(response)
  File "/home/anisse9/bot_app/.env/lib/python3.8/site-packages/ftx/api.py", line 68, in _process_response
    raise Exception(data['error'])
Exception: No such market: ATO/USD 
#  02/10/2022 21:00:02
# bot BOTRIX_ETH_HEL executed
# bot BOTRIX_ETH_ANI executed
# bot BOTRIX_MATIC_ANI executed
# bot BOTRIX executed
Traceback (most recent call last):
  File "./templates/trix_template/TrixFtxlive.py", line 70, in <module>
    data = client.get_historical_data(
  File "/home/anisse9/bot_app/.env/lib/python3.8/site-packages/ftx/api.py", line 415, in get_historical_data
    return self._get(
  File "/home/anisse9/bot_app/.env/lib/python3.8/site-packages/ftx/api.py", line 25, in _get
    return self._request('GET', path, params=params)
  File "/home/anisse9/bot_app/.env/lib/python3.8/site-packages/ftx/api.py", line 41, in _request
    return self._process_response(response)
  File "/home/anisse9/bot_app/.env/lib/python3.8/site-packages/ftx/api.py", line 68, in _process_response
    raise Exception(data['error'])
Exception: No such market: ATO/USD 
#  02/10/2022 22:00:02
# bot BOTRIX_ETH_HEL executed
# bot BOTRIX_ETH_ANI executed
# bot BOTRIX_MATIC_ANI executed
# bot BOTRIX executed
Traceback (most recent call last):
  File "./templates/trix_template/TrixFtxlive.py", line 70, in <module>
    data = client.get_historical_data(
  File "/home/anisse9/bot_app/.env/lib/python3.8/site-packages/ftx/api.py", line 415, in get_historical_data
    return self._get(
  File "/home/anisse9/bot_app/.env/lib/python3.8/site-packages/ftx/api.py", line 25, in _get
    return self._request('GET', path, params=params)
  File "/home/anisse9/bot_app/.env/lib/python3.8/site-packages/ftx/api.py", line 41, in _request
    return self._process_response(response)
  File "/home/anisse9/bot_app/.env/lib/python3.8/site-packages/ftx/api.py", line 68, in _process_response
    raise Exception(data['error'])
Exception: No such market: ATO/USD 
#  02/10/2022 23:00:02
# bot BOTRIX_ETH_HEL executed
# bot BOTRIX_ETH_ANI executed
# bot BOTRIX_MATIC_ANI executed
# bot BOTRIX executed
Traceback (most recent call last):
  File "./templates/trix_template/TrixFtxlive.py", line 70, in <module>
    data = client.get_historical_data(
  File "/home/anisse9/bot_app/.env/lib/python3.8/site-packages/ftx/api.py", line 415, in get_historical_data
    return self._get(
  File "/home/anisse9/bot_app/.env/lib/python3.8/site-packages/ftx/api.py", line 25, in _get
    return self._request('GET', path, params=params)
  File "/home/anisse9/bot_app/.env/lib/python3.8/site-packages/ftx/api.py", line 41, in _request
    return self._process_response(response)
  File "/home/anisse9/bot_app/.env/lib/python3.8/site-packages/ftx/api.py", line 68, in _process_response
    raise Exception(data['error'])
Exception: No such market: ATO/USD 
#  03/10/2022 00:00:03
# bot BOTRIX_ETH_HEL executed
# bot BOTRIX_ETH_ANI executed
# bot BOTRIX_MATIC_ANI executed
# bot BOTRIX executed
Traceback (most recent call last):
  File "./templates/trix_template/TrixFtxlive.py", line 70, in <module>
    data = client.get_historical_data(
  File "/home/anisse9/bot_app/.env/lib/python3.8/site-packages/ftx/api.py", line 415, in get_historical_data
    return self._get(
  File "/home/anisse9/bot_app/.env/lib/python3.8/site-packages/ftx/api.py", line 25, in _get
    return self._request('GET', path, params=params)
  File "/home/anisse9/bot_app/.env/lib/python3.8/site-packages/ftx/api.py", line 41, in _request
    return self._process_response(response)
  File "/home/anisse9/bot_app/.env/lib/python3.8/site-packages/ftx/api.py", line 68, in _process_response
    raise Exception(data['error'])
Exception: No such market: ATO/USD 
#  03/10/2022 01:00:02
on vent :subaccount_name BOTRIX_ETH_HEL
# bot BOTRIX_ETH_HEL executed
on vent :subaccount_name BOTRIX_ETH_ANI
# bot BOTRIX_ETH_ANI executed
# bot BOTRIX_MATIC_ANI executed
on vent :subaccount_name BOTRIX
# bot BOTRIX executed
Traceback (most recent call last):
  File "./templates/trix_template/TrixFtxlive.py", line 70, in <module>
    data = client.get_historical_data(
  File "/home/anisse9/bot_app/.env/lib/python3.8/site-packages/ftx/api.py", line 415, in get_historical_data
    return self._get(
  File "/home/anisse9/bot_app/.env/lib/python3.8/site-packages/ftx/api.py", line 25, in _get
    return self._request('GET', path, params=params)
  File "/home/anisse9/bot_app/.env/lib/python3.8/site-packages/ftx/api.py", line 41, in _request
    return self._process_response(response)
  File "/home/anisse9/bot_app/.env/lib/python3.8/site-packages/ftx/api.py", line 68, in _process_response
    raise Exception(data['error'])
Exception: No such market: ATO/USD 
#  03/10/2022 02:00:02
# bot BOTRIX_ETH_HEL executed
# bot BOTRIX_ETH_ANI executed
# bot BOTRIX_MATIC_ANI executed
# bot BOTRIX executed
Traceback (most recent call last):
  File "./templates/trix_template/TrixFtxlive.py", line 70, in <module>
    data = client.get_historical_data(
  File "/home/anisse9/bot_app/.env/lib/python3.8/site-packages/ftx/api.py", line 415, in get_historical_data
    return self._get(
  File "/home/anisse9/bot_app/.env/lib/python3.8/site-packages/ftx/api.py", line 25, in _get
    return self._request('GET', path, params=params)
  File "/home/anisse9/bot_app/.env/lib/python3.8/site-packages/ftx/api.py", line 41, in _request
    return self._process_response(response)
  File "/home/anisse9/bot_app/.env/lib/python3.8/site-packages/ftx/api.py", line 68, in _process_response
    raise Exception(data['error'])
Exception: No such market: ATO/USD 
#  03/10/2022 03:00:02
# bot BOTRIX_ETH_HEL executed
# bot BOTRIX_ETH_ANI executed
# bot BOTRIX_MATIC_ANI executed
# bot BOTRIX executed
Traceback (most recent call last):
  File "./templates/trix_template/TrixFtxlive.py", line 70, in <module>
    data = client.get_historical_data(
  File "/home/anisse9/bot_app/.env/lib/python3.8/site-packages/ftx/api.py", line 415, in get_historical_data
    return self._get(
  File "/home/anisse9/bot_app/.env/lib/python3.8/site-packages/ftx/api.py", line 25, in _get
    return self._request('GET', path, params=params)
  File "/home/anisse9/bot_app/.env/lib/python3.8/site-packages/ftx/api.py", line 41, in _request
    return self._process_response(response)
  File "/home/anisse9/bot_app/.env/lib/python3.8/site-packages/ftx/api.py", line 68, in _process_response
    raise Exception(data['error'])
Exception: No such market: ATO/USD 
#  03/10/2022 04:00:02
# bot BOTRIX_ETH_HEL executed
# bot BOTRIX_ETH_ANI executed
# bot BOTRIX_MATIC_ANI executed
# bot BOTRIX executed
Traceback (most recent call last):
  File "./templates/trix_template/TrixFtxlive.py", line 70, in <module>
    data = client.get_historical_data(
  File "/home/anisse9/bot_app/.env/lib/python3.8/site-packages/ftx/api.py", line 415, in get_historical_data
    return self._get(
  File "/home/anisse9/bot_app/.env/lib/python3.8/site-packages/ftx/api.py", line 25, in _get
    return self._request('GET', path, params=params)
  File "/home/anisse9/bot_app/.env/lib/python3.8/site-packages/ftx/api.py", line 41, in _request
    return self._process_response(response)
  File "/home/anisse9/bot_app/.env/lib/python3.8/site-packages/ftx/api.py", line 68, in _process_response
    raise Exception(data['error'])
Exception: No such market: ATO/USD 
#  03/10/2022 05:00:02
# bot BOTRIX_ETH_HEL executed
# bot BOTRIX_ETH_ANI executed
# bot BOTRIX_MATIC_ANI executed
# bot BOTRIX executed
Traceback (most recent call last):
  File "./templates/trix_template/TrixFtxlive.py", line 70, in <module>
    data = client.get_historical_data(
  File "/home/anisse9/bot_app/.env/lib/python3.8/site-packages/ftx/api.py", line 415, in get_historical_data
    return self._get(
  File "/home/anisse9/bot_app/.env/lib/python3.8/site-packages/ftx/api.py", line 25, in _get
    return self._request('GET', path, params=params)
  File "/home/anisse9/bot_app/.env/lib/python3.8/site-packages/ftx/api.py", line 41, in _request
    return self._process_response(response)
  File "/home/anisse9/bot_app/.env/lib/python3.8/site-packages/ftx/api.py", line 68, in _process_response
    raise Exception(data['error'])
Exception: No such market: ATO/USD 
#  03/10/2022 06:00:02
# bot BOTRIX_ETH_HEL executed
# bot BOTRIX_ETH_ANI executed
# bot BOTRIX_MATIC_ANI executed
# bot BOTRIX executed
Traceback (most recent call last):
  File "./templates/trix_template/TrixFtxlive.py", line 70, in <module>
    data = client.get_historical_data(
  File "/home/anisse9/bot_app/.env/lib/python3.8/site-packages/ftx/api.py", line 415, in get_historical_data
    return self._get(
  File "/home/anisse9/bot_app/.env/lib/python3.8/site-packages/ftx/api.py", line 25, in _get
    return self._request('GET', path, params=params)
  File "/home/anisse9/bot_app/.env/lib/python3.8/site-packages/ftx/api.py", line 41, in _request
    return self._process_response(response)
  File "/home/anisse9/bot_app/.env/lib/python3.8/site-packages/ftx/api.py", line 68, in _process_response
    raise Exception(data['error'])
Exception: No such market: ATO/USD 
#  03/10/2022 07:00:02
# bot BOTRIX_ETH_HEL executed
# bot BOTRIX_ETH_ANI executed
# bot BOTRIX_MATIC_ANI executed
# bot BOTRIX executed
Traceback (most recent call last):
  File "./templates/trix_template/TrixFtxlive.py", line 70, in <module>
    data = client.get_historical_data(
  File "/home/anisse9/bot_app/.env/lib/python3.8/site-packages/ftx/api.py", line 415, in get_historical_data
    return self._get(
  File "/home/anisse9/bot_app/.env/lib/python3.8/site-packages/ftx/api.py", line 25, in _get
    return self._request('GET', path, params=params)
  File "/home/anisse9/bot_app/.env/lib/python3.8/site-packages/ftx/api.py", line 41, in _request
    return self._process_response(response)
  File "/home/anisse9/bot_app/.env/lib/python3.8/site-packages/ftx/api.py", line 68, in _process_response
    raise Exception(data['error'])
Exception: No such market: ATO/USD 
#  03/10/2022 08:00:02
# bot BOTRIX_ETH_HEL executed
# bot BOTRIX_ETH_ANI executed
# bot BOTRIX_MATIC_ANI executed
# bot BOTRIX executed
Traceback (most recent call last):
  File "./templates/trix_template/TrixFtxlive.py", line 70, in <module>
    data = client.get_historical_data(
  File "/home/anisse9/bot_app/.env/lib/python3.8/site-packages/ftx/api.py", line 415, in get_historical_data
    return self._get(
  File "/home/anisse9/bot_app/.env/lib/python3.8/site-packages/ftx/api.py", line 25, in _get
    return self._request('GET', path, params=params)
  File "/home/anisse9/bot_app/.env/lib/python3.8/site-packages/ftx/api.py", line 41, in _request
    return self._process_response(response)
  File "/home/anisse9/bot_app/.env/lib/python3.8/site-packages/ftx/api.py", line 68, in _process_response
    raise Exception(data['error'])
Exception: No such market: ATO/USD 
#  03/10/2022 09:00:02
# bot BOTRIX_ETH_HEL executed
# bot BOTRIX_ETH_ANI executed
# bot BOTRIX_MATIC_ANI executed
# bot BOTRIX executed
Traceback (most recent call last):
  File "./templates/trix_template/TrixFtxlive.py", line 70, in <module>
    data = client.get_historical_data(
  File "/home/anisse9/bot_app/.env/lib/python3.8/site-packages/ftx/api.py", line 415, in get_historical_data
    return self._get(
  File "/home/anisse9/bot_app/.env/lib/python3.8/site-packages/ftx/api.py", line 25, in _get
    return self._request('GET', path, params=params)
  File "/home/anisse9/bot_app/.env/lib/python3.8/site-packages/ftx/api.py", line 41, in _request
    return self._process_response(response)
  File "/home/anisse9/bot_app/.env/lib/python3.8/site-packages/ftx/api.py", line 68, in _process_response
    raise Exception(data['error'])
Exception: No such market: ATO/USD 
